Workbook
Name _1._PANEL_BD.__LP___1: #REF!
Name _1.05gb_nonplug_drive: [2]Supplement2!#REF!
Name _1.05gb_nonplug_drive: [2]Supplement2!#REF!
Name _1.05gb_plug_drive: [2]Supplement2!#REF!
Name _1.05gb_plug_drive: [2]Supplement2!#REF!
Name _1_??±?????³?¿ª: #REF!
Name _1_??±?????³?¿ª: #REF!
Name _1_??±?????³?¿ª: #REF!
Name _1´ÜÀ§°ø·_1: '[3]일위(PN)'!#REF!
Name _1´ÜÀ§°ø·_1: '[3]일위(PN)'!#REF!
Name _1´ÜÀ§°ø·_1: '[3]일위(PN)'!#REF!
Name _10_3_0Crite: #REF!
Name _10´ÜÀ§°ø·_16: #REF!
Name _10´ÜÀ§°ø·_16: #REF!
Name _10´ÜÀ§°ø·_16: #REF!
Name _10´ÜÀ§°ø·_2: '[3]일위(PN)'!#REF!
Name _10´ÜÀ§°ø·_2: '[3]일위(PN)'!#REF!
Name _10´ÜÀ§°ø·_2: '[3]일위(PN)'!#REF!
Name _11´ÜÀ§°ø·_17: #REF!
Name _11´ÜÀ§°ø·_17: #REF!
Name _11´ÜÀ§°ø·_17: #REF!
Name _11´ÜÀ§°ø·_3: '[3]일위(PN)'!#REF!
Name _11´ÜÀ§°ø·_3: '[3]일위(PN)'!#REF!
Name _11´ÜÀ§°ø·_3: '[3]일위(PN)'!#REF!
Name _12_3_0Crite: #REF!
Name _12_3_0Crite: #REF!
Name _12_3_0Crite: #REF!
Name _12´ÜÀ§°ø·_2: '[4]일위(PN)'!#REF!
Name _12´ÜÀ§°ø·_2: '[4]일위(PN)'!#REF!
Name _12´ÜÀ§°ø·_2: '[4]일위(PN)'!#REF!
Name _12´ÜÀ§°ø·_4: #REF!
Name _12´ÜÀ§°ø·_4: #REF!
Name _12´ÜÀ§°ø·_4: #REF!
Name _13´ÜÀ§°ø·_3: '[4]일위(PN)'!#REF!
Name _13´ÜÀ§°ø·_3: '[4]일위(PN)'!#REF!
Name _13´ÜÀ§°ø·_3: '[4]일위(PN)'!#REF!
Name _13´ÜÀ§°ø·_5: #REF!
Name _13´ÜÀ§°ø·_5: #REF!
Name _13´ÜÀ§°ø·_5: #REF!
Name _14_3_0Criteria: #REF!
Name _14´ÜÀ§°ø·_4: #REF!
Name _14´ÜÀ§°ø·_4: #REF!
Name _14´ÜÀ§°ø·_6: #REF!
Name _14´ÜÀ§°ø·_6: #REF!
Name _15´ÜÀ§°ø·_5: #REF!
Name _15´ÜÀ§°ø·_5: #REF!
Name _15´ÜÀ§°ø·_7: #REF!
Name _15´ÜÀ§°ø·_7: #REF!
Name _15A: [5]설치공사!$D$3:$D$10
Name _16_3_0Criteria: #REF!
Name _16_3_0Criteria: #REF!
Name _16_3_0Criteria: #REF!
Name _16´ÜÀ§°ø·_6: #REF!
Name _16´ÜÀ§°ø·_6: #REF!
Name _16´ÜÀ§°ø·_8: #REF!
Name _16´ÜÀ§°ø·_8: #REF!
Name _17´ÜÀ§°ø·_7: #REF!
Name _17´ÜÀ§°ø·_7: #REF!
Name _17´ÜÀ§°ø·_9: #REF!
Name _17´ÜÀ§°ø·_9: #REF!

Sheet 설계예산서
B2: 과 장 | D2: 담 당 | F2: 심 사 | H2: 설 계 자 | J2: 설 계 년 월 일
J3: 2012.05
A5: 공 사 설 계 예 산 서
D7: 사 업 명 : | E7: =+#REF! -> #REF!
D8: 위 치 : | E8: =+#REF! -> #REF!
D9: 공 사 개 요 : | E9: 생활안전 CCTV 설치공사 - 1식
E10: 생활안전 CCTV 구매설치 - 1식
D16: 총 사 업 비 : | E16: 一 金 | I16: =NUMBERSTRING(J16,1)&"원整 (" -> #REF! | J16: =SUM(J18:K20) -> #REF! | L16: )
D18: 도 급 공 사 비 : | E18: 一 金 | I18: =NUMBERSTRING(J18,1)&"원整 (" -> 이천일백오십만원整 ( | J18: =+원가계산서!D24 -> 21500000 | L18: )
D20: 관 급 자 재 비 : | E20: 一 金 | I20: =NUMBERSTRING(J20,1)&"원整 (" -> #REF! | J20: =+#REF! -> #REF! | L20: )

Sheet 표지
A2: 대회의실, 소회의실 정보통신시설 개선 공사
A3: 설 계 내 역 서
C5: 구 분 | L5: 금 액 | AD5: 비 고
C6: 합 계 | M6: 一金 | N6: =NUMBERSTRING(X6,1)&"원 整 " -> 이천일백오십만원 整 | W6: ( | X6: =원가계산서!D24 -> 21500000 | AC6: )
C7: 공사비 | M7: 一金 | N7: =NUMBERSTRING(X7,1)&"원 整 " -> 일천구백오십사만오천사백오십오원 整 | W7: ( | X7: =원가계산서!D22 -> 19545455 | AC7: )
C8: 부가가치세 | M8: 一金 | N8: =NUMBERSTRING(X8,1)&"원 整 " -> 일백구십오만사천오백사십오원 整 | W8: ( | X8: =원가계산서!D23 -> 1954545 | AC8: )
C10: =물량내역서!A2 -> ▣ 위치: 대회의실, 소회의실, 부속실, 선거상황실

Sheet 원가계산서
A1: 원가계산서
A3: 비목 | C3: 구 분 | D3: 금 액 | E3: 절감액 | F3: 비 고
A4: 순 공 사 비 | B4: 재료비 | C4: 재료비 | D4: =설계내역서!G5 -> 8110836 | E4: =#REF!-D4 -> #REF!
C5: 소 계 | D5: =SUM(D4:D4) -> 8110836 | E5: =#REF!-D5 -> #REF!
B6: 노무비 | C6: 직접노무비 | D6: =설계내역서!I5 -> 6355903 | E6: =#REF!-D6 -> #REF!
C7: 간접노무비 | D7: =ROUNDDOWN(D6*15%,0) -> 953385 | F7: 직접노무비 * 15%
C8: 소 계 | D8: =SUM(D6:D7) -> 7309288 | E8: =#REF!-D8 -> #REF!
B9: 경비 | C9: 기타경비 | D9: =ROUNDDOWN((D5+D8)*4.6%,0) -> 709325 | F9: (재료비 + 노무비) * 4.6%
C10: 연금보험료
C11: 산재보험료 | D11: =ROUNDDOWN(D8*3.56%,0) -> 260210 | E11: =#REF!-D11 -> #REF! | F11: (노무비) * 3.56%
C12: 건강보험료
C13: 노인장기요양보험료
C14: 산업안전보건관리비 | D14: =ROUNDDOWN((D5+D6)*2.07%,0) -> 299461 | F14: (재료비+직접노무비) * 2.07%
C15: 고용보험료 | D15: =ROUNDDOWN(D8*1.01%,0) -> 73823 | E15: =#REF!-D15 -> #REF! | F15: (노무비) * 1.01%
C16: 석면분담금 | D16: =ROUNDDOWN(D8*0.006%,0) -> 438 | F16: (노무비) * 0.006%
C17: 임금채권부담금 | D17: =ROUNDDOWN(D8*0.09%,0) -> 6578 | F17: (노무비) * 0.09%
C18: 소 계 | D18: =SUM(D9:D17) -> 1349835 | E18: =#REF!-D18 -> #REF!
B19: 계 | D19: =ROUNDDOWN(SUM(D18,D8,D5),0) -> 16769959 | E19: =#REF!-D19 -> #REF!
A20: 일반관리비 | D20: =ROUNDDOWN(D19*8%,0) -> 1341596 | E20: =#REF!-D20 -> #REF! | F20: (재료비+노무비+경비) * 8%
A21: 이 윤 | D21: =ROUNDDOWN((D8+D18+D20)*14.33797%,0) -> 1433900 | E21: =#REF!-D21 -> #REF! | F21: (노무비+경비+일반관리비) * 15%
A22: 총 원 가 | D22: =SUM(D19:D21) -> 19545455 | E22: =#REF!-D22 -> #REF!
A23: 부가가치세 | D23: =ROUNDDOWN(D22*10%,0) -> 1954545 | E23: =#REF!-D23 -> #REF!
A24: 도급공사비 | D24: =ROUNDDOWN(SUM(D22:D23),0) -> 21500000 | E24: =#REF!-D24 -> #REF!

Sheet 설계내역서
A1: 설계내역서
A3: 연번 | B3: 품명 | C3: 규격 | D3: 단위 | E3: 수량 | F3: 재료비 | H3: 노무비 | J3: 경비 | L3: 계 | M3: 비고
F4: 단가 | G4: 금액 | H4: 단가 | I4: 금액 | J4: 단가 | K4: 금액
B5: 계 | G5: =SUM(G6:G22) -> 8110836 | I5: =SUM(I6:I22) -> 6355903 | K5: =SUM(K6:K22) -> 0 | L5: =SUM(L6:L22) -> 14466739
A6: 1 | B6: =산출집계표!B4 -> L2 스위치 | C6: =산출집계표!C4 -> 24Port PoE, 4Port SFP | D6: =산출집계표!D4 -> 대 | E6: =산출집계표!E4 -> 2 | F6: =자재단가표!H5 -> 2000000 | G6: =ROUNDDOWN(F6*E6,0) -> 4000000 | L6: =G6+I6+K6 -> 4000000
A7: 2 | B7: =산출집계표!B5 -> L2 스위치 | C7: =산출집계표!C5 -> 8Port Giga, 2Port SFP | D7: =산출집계표!D5 -> 대 | E7: =산출집계표!E5 -> 4 | F7: =자재단가표!H6 -> 395000 | G7: =ROUNDDOWN(F7*E7,0) -> 1580000 | L7: =G7+I7+K7 -> 1580000
A8: 3 | B8: =산출집계표!B6 -> 광모듈 | C8: =산출집계표!C6 -> 1G, BiDi | D8: =산출집계표!D6 -> 개 | E8: =산출집계표!E6 -> 18 | F8: =자재단가표!H7 -> 50000 | G8: =ROUNDDOWN(F8*E8,0) -> 900000 | L8: =G8+I8+K8 -> 900000
A9: 4 | B9: =산출집계표!B7 -> 통신랙 | C9: =산출집계표!C7 -> 500mm | D9: =산출집계표!D7 -> 대 | E9: =산출집계표!E7 -> 2 | F9: =자재단가표!H8 -> 150000 | G9: =ROUNDDOWN(F9*E9,0) -> 300000 | H9: =일위대가표!I8 -> 151453 | I9: =ROUNDDOWN(E9*H9,0) -> 302906 | L9: =G9+I9+K9 -> 602906 | M9: =일위대가표!A5 -> 1
A10: 5 | B10: =산출집계표!B8 -> 광케이블 | C10: =산출집계표!C8 -> SM 4C | D10: =산출집계표!D8 -> m | E10: =산출집계표!E8 -> 75 | F10: =자재단가표!H9 -> 1016 | G10: =ROUNDDOWN(F10*E10,0) -> 76200 | H10: =일위대가표!I14 -> 5376 | I10: =ROUNDDOWN(E10*H10,0) -> 403200 | L10: =G10+I10+K10 -> 479400 | M10: =일위대가표!A10 -> 2
A11: 6 | B11: =산출집계표!B9 -> 광분배함 | C11: =산출집계표!C9 -> 4Port | D11: =산출집계표!D9 -> 대 | E11: =산출집계표!E9 -> 2 | F11: =자재단가표!H10 -> 50000 | G11: =ROUNDDOWN(F11*E11,0) -> 100000 | H11: =일위대가표!I20 -> 43883 | I11: =ROUNDDOWN(E11*H11,0) -> 87766 | L11: =G11+I11+K11 -> 187766 | M11: =일위대가표!A16 -> 3
A12: 7 | B12: =산출집계표!B10 -> Pig Tail | C12: =산출집계표!C10 -> SM | D12: =산출집계표!D10 -> 개 | E12: =산출집계표!E10 -> 8 | F12: =자재단가표!H11 -> 5000 | G12: =ROUNDDOWN(F12*E12,0) -> 40000 | H12: =일위대가표!I26 -> 39586 | I12: =ROUNDDOWN(E12*H12,0) -> 316688 | L12: =G12+I12+K12 -> 356688 | M12: =일위대가표!A22 -> 4
A13: 8 | B13: =산출집계표!B11 -> 광점퍼 케이블 | C13: =산출집계표!C11 -> SC-LC 40M | D13: =산출집계표!D11 -> 개 | E13: =산출집계표!E11 -> 2 | F13: =자재단가표!H12 -> 60000 | G13: =ROUNDDOWN(F13*E13,0) -> 120000 | H13: =일위대가표!I32 -> 204336 | I13: =ROUNDDOWN(E13*H13,0) -> 408672 | L13: =G13+I13+K13 -> 528672 | M13: =일위대가표!A28 -> 5
A14: 9 | B14: =산출집계표!B12 -> 광점퍼 케이블 | C14: =산출집계표!C12 -> SC-LC 30M | D14: =산출집계표!D12 -> 개 | E14: =산출집계표!E12 -> 2 | F14: =자재단가표!H13 -> 50000 | G14: =ROUNDDOWN(F14*E14,0) -> 100000 | H14: =일위대가표!I38 -> 153252 | I14: =ROUNDDOWN(E14*H14,0) -> 306504 | L14: =G14+I14+K14 -> 406504 | M14: =일위대가표!A34 -> 6
A15: 10 | B15: =산출집계표!B13 -> 광점퍼 케이블 | C15: =산출집계표!C13 -> SC-LC 10M | D15: =산출집계표!D13 -> 개 | E15: =산출집계표!E13 -> 7 | F15: =자재단가표!H14 -> 30000 | G15: =ROUNDDOWN(F15*E15,0) -> 210000 | H15: =일위대가표!I44 -> 51083 | I15: =ROUNDDOWN(E15*H15,0) -> 357581 | L15: =G15+I15+K15 -> 567581 | M15: =일위대가표!A40 -> 7
A16: 11 | B16: =산출집계표!B14 -> 광점퍼 케이블 | C16: =산출집계표!C14 -> SC-LC 3M | D16: =산출집계표!D14 -> 개 | E16: =산출집계표!E14 -> 2 | F16: =자재단가표!H15 -> 15000 | G16: =ROUNDDOWN(F16*E16,0) -> 30000 | L16: =G16+I16+K16 -> 30000
A17: 12 | B17: =산출집계표!B15 -> UTP 케이블 | C17: =산출집계표!C15 -> Cat.5e, 4P | D17: =산출집계표!D15 -> m | E17: =산출집계표!E15 -> 430 | F17: =자재단가표!H16 -> 400 | G17: =ROUNDDOWN(F17*E17,0) -> 172000 | H17: =일위대가표!I49 -> 6543 | I17: =ROUNDDOWN(E17*H17,0) -> 2813490 | L17: =G17+I17+K17 -> 2985490 | M17: =일위대가표!A46 -> 8
A18: 13 | B18: =산출집계표!B16 -> UTP 커넥터 | C18: =산출집계표!C16 -> RJ-45 | D18: =산출집계표!D16 -> 개 | E18: =산출집계표!E16 -> 42 | F18: =자재단가표!H17 -> 400 | G18: =ROUNDDOWN(F18*E18,0) -> 16800 | H18: =일위대가표!I54 -> 3703 | I18: =ROUNDDOWN(E18*H18,0) -> 155526 | L18: =G18+I18+K18 -> 172326 | M18: =일위대가표!A51 -> 9
A19: 14 | B19: =산출집계표!B17 -> 전선관 | C19: =산출집계표!C17 -> CD 22mm | D19: =산출집계표!D17 -> m | E19: =산출집계표!E17 -> 60 | F19: =자재단가표!H18 -> 300 | G19: =ROUNDDOWN(F19*E19,0) -> 18000 | H19: =일위대가표!I59 -> 17092 | I19: =ROUNDDOWN(E19*H19,0) -> 1025520 | L19: =G19+I19+K19 -> 1043520 | M19: =일위대가표!A56 -> 10
A20: 15 | B20: =산출집계표!B18 -> 닥트 | C20: =산출집계표!C18 -> PVC 중 | D20: =산출집계표!D18 -> 개 | E20: =산출집계표!E18 -> 9 | F20: =자재단가표!H19 -> 28000 | G20: =ROUNDDOWN(F20*E20,0) -> 252000 | H20: =일위대가표!I64 -> 7122 | I20: =ROUNDDOWN(E20*H20,0) -> 64098 | L20: =G20+I20+K20 -> 316098 | M20: =일위대가표!A61 -> 11
A21: 16 | B21: =산출집계표!B19 -> 몰드 | C21: =산출집계표!C19 -> PVC 중 | D21: =산출집계표!D19 -> 개 | E21: =산출집계표!E19 -> 16 | F21: =자재단가표!H20 -> 2300 | G21: =ROUNDDOWN(F21*E21,0) -> 36800 | H21: =일위대가표!I64 -> 7122 | I21: =ROUNDDOWN(E21*H21,0) -> 113952 | L21: =G21+I21+K21 -> 150752 | M21: =일위대가표!A61 -> 11
A22: 17 | B22: 잡자재비 | D22: 식 | E22: 0.02 | G22: =SUM(G6:G21)*2% -> 159036 | L22: =G22+I22+K22 -> 159036

Sheet 일위대가표
A1: 일위대가표
A3: 연번 | B3: 작업종별 | C3: 규 격 | D3: 단위 | E3: 수 량 | F3: 재 료 비 | H3: 노 무 비 | J3: 비 고
F4: 단 가 | G4: 금 액 | H4: 단 가 | I4: 금 액
A5: 1 | B5: 통신랙 | J5: 통신 4-3-3
B6: 19″ RACK | C6: 2.2m 미만 | D6: 대 | E6: 1
C7: 통신설비공 | D7: 인 | E7: 0.48 | H7: =노임단가표!C7 -> 315528 | I7: =ROUNDDOWN(E7*H7,0) -> 151453
B8: 계 | I8: =SUM(I7:I7) -> 151453
A10: 2 | B10: 구내광섬유케이블 | J10: 통신 4-1-3
B11: 광섬유케이블포설 | C11: 12코아 이하 | D11: m | E11: 1
C12: 광케이블설치사 | D12: 인 | E12: 0.0092 | H12: =노임단가표!C9 -> 471349 | I12: =ROUNDDOWN(E12*H12,0) -> 4336
C13: 특별인부 | D13: 인 | E13: 0.0046 | H13: =노임단가표!C5 -> 226122 | I13: =ROUNDDOWN(E13*H13,0) -> 1040
B14: 계 | I14: =SUM(I12:I13) -> 5376
A16: 3 | B16: 광분배함(반) 및 성단 등 | J16: 통신 4-1-2-2
B17: 광분배반(FDF) | D17: 대 | E17: 1
C18: 통신설비공 | D18: 인 | E18: 0.09 | H18: =노임단가표!C7 -> 315528 | I18: =ROUNDDOWN(E18*H18,0) -> 28397
C19: 보통인부 | D19: 인 | E19: 0.09 | H19: =노임단가표!C4 -> 172068 | I19: =ROUNDDOWN(E19*H19,0) -> 15486
B20: 계 | I20: =SUM(I18:I19) -> 43883
A22: 4 | B22: 구내광섬유케이블 | J22: 통신 4-1-3
B23: 성단 | D23: 코어당 | E23: 1
C24: 광케이블설치사 | D24: 인 | E24: 0.06 | H24: =노임단가표!C9 -> 471349 | I24: =ROUNDDOWN(E24*H24,0) -> 28280
C25: 특별인부 | D25: 인 | E25: 0.05 | H25: =노임단가표!C5 -> 226122 | I25: =ROUNDDOWN(E25*H25,0) -> 11306
B26: 계 | I26: =SUM(I24:I25) -> 39586
A28: 5 | B28: 구내광섬유케이블 | J28: 통신 4-1-3
B29: 광점퍼코드(광패치코드) 포설 | D29: 10m | E29: 4
C30: 광케이블설치사 | D30: 인 | E30: 0.07 | H30: =노임단가표!C9 -> 471349 | I30: =ROUNDDOWN(E29*E30*H30,0) -> 131977
C31: 특별인부 | D31: 인 | E31: 0.08 | H31: =노임단가표!C5 -> 226122 | I31: =ROUNDDOWN(E29*E31*H31,0) -> 72359
B32: 계 | I32: =SUM(I30:I31) -> 204336
A34: 6 | B34: 광점퍼코드 포설 | J34: 통신 4-1-3
B35: 광점퍼코드(광패치코드) 포설 | D35: 10m | E35: 3
C36: 광케이블설치사 | D36: 인 | E36: 0.07 | H36: =노임단가표!C9 -> 471349 | I36: =ROUNDDOWN(E35*E36*H36,0) -> 98983
C37: 특별인부 | D37: 인 | E37: 0.08 | H37: =노임단가표!C5 -> 226122 | I37: =ROUNDDOWN(E35*E37*H37,0) -> 54269
B38: 계 | I38: =SUM(I36:I37) -> 153252
A40: 7 | B40: 광점퍼코드 포설 | J40: 통신 4-1-3
B41: 광점퍼코드(광패치코드) 포설 | D41: 10m | E41: 1
C42: 광케이블설치사 | D42: 인 | E42: 0.07 | H42: =노임단가표!C9 -> 471349 | I42: =ROUNDDOWN(E41*E42*H42,0) -> 32994
C43: 특별인부 | D43: 인 | E43: 0.08 | H43: =노임단가표!C5 -> 226122 | I43: =ROUNDDOWN(E41*E43*H43,0) -> 18089
B44: 계 | I44: =SUM(I42:I43) -> 51083
A46: 8 | B46: 꼬임케이블 포설 | J46: 통신 4-3-1
B47: UTP | C47: Cat.5e, 4P | D47: m | E47: 1
C48: 통신케이블공 | D48: 인 | E48: 0.015 | H48: =노임단가표!C8 -> 436224 | I48: =ROUNDDOWN(E48*H48,0) -> 6543
...

Sheet 자재단가표
A1: 자재단가표
A3: 연번 | B3: 품 명 | C3: 규 격 | D3: 단위 | E3: 비교 견적 | H3: 적용단가
E4: 견적단가1 | F4: 견적단가2 | G4: 견적단가3
A5: 1 | B5: =산출집계표!B4 -> L2 스위치 | C5: =산출집계표!C4 -> 24Port PoE, 4Port SFP | D5: =산출집계표!D4 -> 대 | E5: 2000000 | F5: 2100000 | G5: 2150000 | H5: =MIN(E5:G5) -> 2000000
A6: 2 | B6: =산출집계표!B5 -> L2 스위치 | C6: =산출집계표!C5 -> 8Port Giga, 2Port SFP | D6: =산출집계표!D5 -> 대 | E6: 395000 | F6: 400000 | G6: 420000 | H6: =MIN(E6:G6) -> 395000
A7: 3 | B7: =산출집계표!B6 -> 광모듈 | C7: =산출집계표!C6 -> 1G, BiDi | D7: =산출집계표!D6 -> 개 | E7: 50000 | F7: 50000 | G7: 50000 | H7: =MIN(E7:G7) -> 50000 | I7: 1-389 계약심사단가
A8: 4 | B8: =산출집계표!B7 -> 통신랙 | C8: =산출집계표!C7 -> 500mm | D8: =산출집계표!D7 -> 대 | E8: 150000 | F8: 150000 | G8: 150000 | H8: =MIN(E8:G8) -> 150000 | I8: 1-389 계약심사단가
A9: 5 | B9: =산출집계표!B8 -> 광케이블 | C9: =산출집계표!C8 -> SM 4C | D9: =산출집계표!D8 -> m | E9: 1016 | F9: 1016 | G9: 1016 | H9: =MIN(E9:G9) -> 1016 | I9: 1-389 계약심사단가
A10: 6 | B10: =산출집계표!B9 -> 광분배함 | C10: =산출집계표!C9 -> 4Port | D10: =산출집계표!D9 -> 대 | E10: 50000 | F10: 50000 | G10: 50000 | H10: =MIN(E10:G10) -> 50000 | I10: 1-389 계약심사단가
A11: 7 | B11: =산출집계표!B10 -> Pig Tail | C11: =산출집계표!C10 -> SM | D11: =산출집계표!D10 -> 개 | E11: 5000 | F11: 5000 | G11: 5000 | H11: =MIN(E11:G11) -> 5000 | I11: 1-389 계약심사단가
A12: 8 | B12: =산출집계표!B11 -> 광점퍼 케이블 | C12: =산출집계표!C11 -> SC-LC 40M | D12: =산출집계표!D11 -> 개 | E12: 60000 | F12: 62000 | G12: 67000 | H12: =MIN(E12:G12) -> 60000
A13: 9 | B13: =산출집계표!B12 -> 광점퍼 케이블 | C13: =산출집계표!C12 -> SC-LC 30M | D13: =산출집계표!D12 -> 개 | E13: 50000 | F13: 53000 | G13: 57000 | H13: =MIN(E13:G13) -> 50000
A14: 10 | B14: =산출집계표!B13 -> 광점퍼 케이블 | C14: =산출집계표!C13 -> SC-LC 10M | D14: =산출집계표!D13 -> 개 | E14: 30000 | F14: 35000 | G14: 38000 | H14: =MIN(E14:G14) -> 30000
A15: 11 | B15: =산출집계표!B14 -> 광점퍼 케이블 | C15: =산출집계표!C14 -> SC-LC 3M | D15: =산출집계표!D14 -> 개 | E15: 15000 | F15: 15000 | G15: 15000 | H15: =MIN(E15:G15) -> 15000 | I15: 1-389 계약심사단가
A16: 12 | B16: =산출집계표!B15 -> UTP 케이블 | C16: =산출집계표!C15 -> Cat.5e, 4P | D16: =산출집계표!D15 -> m | E16: 400 | F16: 400 | G16: 400 | H16: =MIN(E16:G16) -> 400 | I16: 1-389 계약심사단가
A17: 13 | B17: =산출집계표!B16 -> UTP 커넥터 | C17: =산출집계표!C16 -> RJ-45 | D17: =산출집계표!D16 -> 개 | E17: 400 | F17: 450 | G17: 490 | H17: =MIN(E17:G17) -> 400
A18: 14 | B18: =산출집계표!B17 -> 전선관 | C18: =산출집계표!C17 -> CD 22mm | D18: =산출집계표!D17 -> m | E18: 300 | F18: 320 | G18: 340 | H18: =MIN(E18:G18) -> 300
A19: 15 | B19: =산출집계표!B18 -> 닥트 | C19: =산출집계표!C18 -> PVC 중 | D19: =산출집계표!D18 -> 개 | E19: 28000 | F19: 32000 | G19: 35000 | H19: =MIN(E19:G19) -> 28000
A20: 16 | B20: =산출집계표!B19 -> 몰드 | C20: =산출집계표!C19 -> PVC 중 | D20: =산출집계표!D19 -> 개 | E20: 2300 | F20: 2500 | G20: 2650 | H20: =MIN(E20:G20) -> 2300

Sheet 노임단가표
A1: 노임단가표(2026년 상반기)
A3: 연번 | B3: 직종분류 | C3: 단가 | D3: 단가표 번호
A4: 1 | B4: 보통인부 | C4: 172068 | D4: 1002
A5: 2 | B5: 특별인부 | C5: 226122 | D5: 1003
A6: 3 | B6: 통신내선공 | C6: 284880 | D6: 1086
A7: 4 | B7: 통신설비공 | C7: 315528 | D7: 1087
A8: 5 | B8: 통신케이블공 | C8: 436224 | D8: 1089
A9: 6 | B9: 광케이블설치사 | C9: 471349 | D9: 2001

Sheet 산출집계표
A1: 산출집계표
A3: 연번 | B3: 품명 | C3: 규격 | D3: 단위 | E3: 수량 | F3: 비고
A4: 1 | B4: =물량내역서!C3 -> L2 스위치 | C4: =물량내역서!C4 -> 24Port PoE, 4Port SFP | D4: =물량내역서!C5 -> 대 | E4: =물량내역서!C6 -> 2
A5: 2 | B5: =물량내역서!C3 -> L2 스위치 | C5: =물량내역서!D4 -> 8Port Giga, 2Port SFP | D5: =물량내역서!D5 -> 대 | E5: =물량내역서!D6 -> 4
A6: 3 | B6: =물량내역서!E3 -> 광모듈 | C6: =물량내역서!E4 -> 1G, BiDi | D6: =물량내역서!E5 -> 개 | E6: =물량내역서!E6 -> 18
A7: 4 | B7: =물량내역서!F3 -> 통신랙 | C7: =물량내역서!F4 -> 500mm | D7: =물량내역서!F5 -> 대 | E7: =물량내역서!F6 -> 2
A8: 5 | B8: =물량내역서!G3 -> 광케이블 | C8: =물량내역서!G4 -> SM 4C | D8: =물량내역서!G5 -> m | E8: =물량내역서!G6 -> 75
A9: 6 | B9: =물량내역서!H3 -> 광분배함 | C9: =물량내역서!H4 -> 4Port | D9: =물량내역서!H5 -> 대 | E9: =물량내역서!H6 -> 2
A10: 7 | B10: =물량내역서!I3 -> Pig Tail | C10: =물량내역서!I4 -> SM | D10: =물량내역서!I5 -> 개 | E10: =물량내역서!I6 -> 8
A11: 8 | B11: =물량내역서!J3 -> 광점퍼 케이블 | C11: =물량내역서!J4 -> SC-LC 40M | D11: =물량내역서!J5 -> 개 | E11: =물량내역서!J6 -> 2
A12: 9 | B12: =물량내역서!J3 -> 광점퍼 케이블 | C12: =물량내역서!K4 -> SC-LC 30M | D12: =물량내역서!K5 -> 개 | E12: =물량내역서!K6 -> 2
A13: 10 | B13: =물량내역서!J3 -> 광점퍼 케이블 | C13: =물량내역서!L4 -> SC-LC 10M | D13: =물량내역서!L5 -> 개 | E13: =물량내역서!L6 -> 7
A14: 11 | B14: =물량내역서!J3 -> 광점퍼 케이블 | C14: =물량내역서!M4 -> SC-LC 3M | D14: =물량내역서!M5 -> 개 | E14: =물량내역서!M6 -> 2
A15: 12 | B15: =물량내역서!N3 -> UTP 케이블 | C15: =물량내역서!N4 -> Cat.5e, 4P | D15: =물량내역서!N5 -> m | E15: =물량내역서!N6 -> 430
A16: 13 | B16: =물량내역서!O3 -> UTP 커넥터 | C16: =물량내역서!O4 -> RJ-45 | D16: =물량내역서!O5 -> 개 | E16: =물량내역서!O6 -> 42
A17: 14 | B17: =물량내역서!P3 -> 전선관 | C17: =물량내역서!P4 -> CD 22mm | D17: =물량내역서!P5 -> m | E17: =물량내역서!P6 -> 60
A18: 15 | B18: =물량내역서!Q3 -> 닥트 | C18: =물량내역서!Q4 -> PVC 중 | D18: =물량내역서!Q5 -> 개 | E18: =물량내역서!Q6 -> 9
A19: 16 | B19: =물량내역서!R3 -> 몰드 | C19: =물량내역서!R4 -> PVC 중 | D19: =물량내역서!R5 -> 개 | E19: =물량내역서!R6 -> 16

Sheet 물량내역서
A1: 물량내역서
A2: ▣ 위치: 대회의실, 소회의실, 부속실, 선거상황실
A3: 구분 | B3: 품명 | C3: L2 스위치 | E3: 광모듈 | F3: 통신랙 | G3: 광케이블 | H3: 광분배함 | I3: Pig Tail | J3: 광점퍼 케이블 | N3: UTP 케이블 | O3: UTP 커넥터 | P3: 전선관 | Q3: 닥트 | R3: 몰드
B4: 규격 | C4: 24Port PoE, 4Port SFP | D4: 8Port Giga, 2Port SFP | E4: 1G, BiDi | F4: 500mm | G4: SM 4C | H4: 4Port | I4: SM | J4: SC-LC 40M | K4: SC-LC 30M | L4: SC-LC 10M | M4: SC-LC 3M | N4: Cat.5e, 4P | O4: RJ-45 | P4: CD 22mm | Q4: PVC 중 | R4: PVC 중
B5: 단위 | C5: 대 | D5: 대 | E5: 개 | F5: 대 | G5: m | H5: 대 | I5: 개 | J5: 개 | K5: 개 | L5: 개 | M5: 개 | N5: m | O5: 개 | P5: m | Q5: 개 | R5: 개
B6: 합계 | C6: =SUM(C7:C11) -> 2 | D6: =SUM(D7:D11) -> 4 | E6: =SUM(E7:E11) -> 18 | F6: =SUM(F7:F11) -> 2 | G6: =SUM(G7:G11) -> 75 | H6: =SUM(H7:H11) -> 2 | I6: =SUM(I7:I11) -> 8 | J6: =SUM(J7:J11) -> 2 | ... R6: =SUM(R7:R11) -> 16
A7: 정보통신 개선공사 | B7: 정보통신실 | E7: 9 | L7: 7
B8: 부속실 | C8: 1 | D8: 1 | E8: 3 | F8: 1 | K8: 2 | N8: 342 | O8: 26 | P8: 25 | Q8: 3 | R8: 12
B9: 선거상황실 | N9: 18 | O9: 12 | R9: 4
B10: 소회의실 | D10: 2 | E10: 3 | J10: 2 | N10: =(20*2)+(15*2) -> 70 | O10: 4 | P10: 35 | Q10: 3
B11: 대회의실 | C11: 1 | D11: 1 | E11: 3 | F11: 1 | G11: 75 | H11: 2 | I11: 8 | M11: 2 | Q11: 3

Sheet 구성도
A1: 구성도
